Workbook

Sheet Principal
A1: Región | B1: PA | C1: Nombre (Punto de Acceso) | D1: Provincia | E1: Distrito | F1: Corregimiento | G1: Tipo UM | H1: Latitud | I1: Longitud | J1: Fecha de Activación | K1: Tiempo Activo (Años) | L1: Datos (GB) | M1: Cantidad de Sesiones | N1: Promedio de Datos Consumidos por Sesión (MB) | O1: Proveedor | P1: Disponibilidad del Punto de Acceso | Q1: Nombres de Centros Educativos (MEDUCA) | R1: Dependencia | S1: Estatus | T1: Área | U1: Indígena | V1: Nivel Educativo (Oferta 2023) | W1: Centros Educativos sin Punto de Acceso a Internet de la RNI
A2: 1 | B2: 1366 | C2: Escuela Finca 66 | D2: Bocas del Toro | E2: Changuinola | F2: Changuinola | G2: FO | H2: 9.446004 | I2: -82.517252 | J2: 42915 | K2: =(TODAY()-Table1[[#This Row],[Fecha de Activación]])/365 -> 8.460274 | L2: =VLOOKUP(Table1[[#This Row],[Nombre (Punto de Acceso)]],BD_DataTransferida!A29:G82,7,FALSE) -> 348 | M2: =VLOOKUP(Table1[[#This Row],[Nombre (Punto de Acceso)]],BD_Sesiones!A28:I82,7,FALSE) -> 823 | N2: =TRUNC(Table1[[#This Row],[Datos (GB)]]/Table1[[#This Row],[Cantidad de Sesiones]]*1024) -> 432 | O2: =VLOOKUP(Table1[[#This Row],[Nombre (Punto de Acceso)]],BD_Sesiones!A28:I82,8,FALSE) -> C&W Panamá | P2: =VLOOKUP(Table1[[#This Row],[Nombre (Punto de Acceso)]],BD_Sesiones!A28:I82,9,FALSE) -> Sí | Q2: ESC. BILINGÜE FINCA 66 | R2: =VLOOKUP(Table1[[#This Row],[Nombres de Centros Educativos (MEDUCA)]],BD_Meduca!A8:N58,9,FALSE) -> PARTICULAR | S2: =VLOOKUP(Table1[[#This Row],[Nombres de Centros Educativos (MEDUCA)]],BD_Meduca!A8:N58,10,FALSE) -> ACTIVA | T2: =VLOOKUP(Table1[[#This Row],[Nombres de Centros Educativos (MEDUCA)]],BD_Meduca!A8:N61,7,FALSE) -> URBANA | U2: =VLOOKUP(Table1[[#This Row],[Nombres de Centros Educativos (MEDUCA)]],BD_Meduca!A8:N61,11,FALSE) -> NO | V2: =VLOOKUP(Table1[[#This Row],[Nombres de Centros Educativos (MEDUCA)]],BD_Meduca!A8:N61,14,FALSE) -> PREMEDIA | W2: TERMINACION PRIMARIA NIEVECITA
A3: 1 | B3: 37 | C3: Escuela Finca 3 | D3: Bocas del Toro | E3: Changuinola | F3: El Empalme | G3: Satelital | H3: 9.424643 | I3: -82.471711 | J3: 43088 | K3: =(TODAY()-Table1[[#This Row],[Fecha de Activación]])/365 -> 7.9863014 | L3: =VLOOKUP(Table1[[#This Row],[Nombre (Punto de Acceso)]],BD_DataTransferida!A22:G75,7,FALSE) -> 124 | M3: =VLOOKUP(Table1[[#This Row],[Nombre (Punto de Acceso)]],BD_Sesiones!A21:I75,7,FALSE) -> 313 | N3: =TRUNC(Table1[[#This Row],[Datos (GB)]]/Table1[[#This Row],[Cantidad de Sesiones]]*1024) -> 405 | O3: =VLOOKUP(Table1[[#This Row],[Nombre (Punto de Acceso)]],BD_Sesiones!A21:I75,8,FALSE) -> C&W Panamá | P3: =VLOOKUP(Table1[[#This Row],[Nombre (Punto de Acceso)]],BD_Sesiones!A21:I75,9,FALSE) -> Sí | Q3: ESC. FINCA 03 | R3: =VLOOKUP(Table1[[#This Row],[Nombres de Centros Educativos (MEDUCA)]],BD_Meduca!A8:N59,9,FALSE) -> OFICIAL | S3: =VLOOKUP(Table1[[#This Row],[Nombres de Centros Educativos (MEDUCA)]],BD_Meduca!A8:N59,10,FALSE) -> ACTIVA | T3: =VLOOKUP(Table1[[#This Row],[Nombres de Centros Educativos (MEDUCA)]],BD_Meduca!A9:N62,7,FALSE) -> INDIGENA | U3: =VLOOKUP(Table1[[#This Row],[Nombres de Centros Educativos (MEDUCA)]],BD_Meduca!A9:N62,11,FALSE) -> SI | V3: =VLOOKUP(Table1[[#This Row],[Nombres de Centros Educativos (MEDUCA)]],BD_Meduca!A9:N62,14,FALSE) -> PRIMARIA | W3: C.E.B.G. BAJO CEDRO
A4: 1 | B4: 47 | C4: Escuela Puente blanco | D4: Bocas del Toro | E4: Changuinola | F4: Guabito | G4: PTP | H4: 9.481746 | I4: -82.595249 | J4: 42914 | K4: =(TODAY()-Table1[[#This Row],[Fecha de Activación]])/365 -> 8.4630137 | L4: =VLOOKUP(Table1[[#This Row],[Nombre (Punto de Acceso)]],BD_DataTransferida!A34:G87,7,FALSE) -> 718 | M4: =VLOOKUP(Table1[[#This Row],[Nombre (Punto de Acceso)]],BD_Sesiones!A33:I87,7,FALSE) -> 2808 | N4: =TRUNC(Table1[[#This Row],[Datos (GB)]]/Table1[[#This Row],[Cantidad de Sesiones]]*1024) -> 261 | O4: =VLOOKUP(Table1[[#This Row],[Nombre (Punto de Acceso)]],BD_Sesiones!A33:I87,8,FALSE) -> C&W Panamá | P4: =VLOOKUP(Table1[[#This Row],[Nombre (Punto de Acceso)]],BD_Sesiones!A33:I87,9,FALSE) -> Sí | Q4: ESC. PUENTE BLANCO | R4: =VLOOKUP(Table1[[#This Row],[Nombres de Centros Educativos (MEDUCA)]],BD_Meduca!A9:N63,9,FALSE) -> OFICIAL | S4: =VLOOKUP(Table1[[#This Row],[Nombres de Centros Educativos (MEDUCA)]],BD_Meduca!A9:N63,10,FALSE) -> ACTIVA | T4: =VLOOKUP(Table1[[#This Row],[Nombres de Centros Educativos (MEDUCA)]],BD_Meduca!A11:N66,7,FALSE) -> INDIGENA | U4: =VLOOKUP(Table1[[#This Row],[Nombres de Centros Educativos (MEDUCA)]],BD_Meduca!A11:N66,11,FALSE) -> SI | V4: =VLOOKUP(Table1[[#This Row],[Nombres de Centros Educativos (MEDUCA)]],BD_Meduca!A11:N66,14,FALSE) -> PREESCOLAR-PRIMARIA | W4: C.E.B.G. BILINGÜE CHANGUINOLA
A5: 1 | B5: 10 | C5: Escuela Miraflores | D5: Bocas del Toro | E5: Almirante | F5: Puerto Almirante | G5: FO | H5: 9.305504 | I5: -82.437321 | J5: 42926 | K5: =(TODAY()-Table1[[#This Row],[Fecha de Activación]])/365 -> 8.430137 | L5: =VLOOKUP(Table1[[#This Row],[Nombre (Punto de Acceso)]],BD_DataTransferida!A32:G85,7,FALSE) -> 592 | M5: =VLOOKUP(Table1[[#This Row],[Nombre (Punto de Acceso)]],BD_Sesiones!A31:I85,7,FALSE) -> 2364 | N5: =TRUNC(Table1[[#This Row],[Datos (GB)]]/Table1[[#This Row],[Cantidad de Sesiones]]*1024) -> 256 | O5: =VLOOKUP(Table1[[#This Row],[Nombre (Punto de Acceso)]],BD_Sesiones!A31:I85,8,FALSE) -> C&W Panamá | P5: =VLOOKUP(Table1[[#This Row],[Nombre (Punto de Acceso)]],BD_Sesiones!A31:I85,9,FALSE) -> Sí | Q5: ESC. MIRAFLORES | R5: =VLOOKUP(Table1[[#This Row],[Nombres de Centros Educativos (MEDUCA)]],BD_Meduca!A8:N61,9,FALSE) -> OFICIAL | S5: =VLOOKUP(Table1[[#This Row],[Nombres de Centros Educativos (MEDUCA)]],BD_Meduca!A8:N61,10,FALSE) -> ACTIVA | T5: =VLOOKUP(Table1[[#This Row],[Nombres de Centros Educativos (MEDUCA)]],BD_Meduca!A10:N64,7,FALSE) -> RURAL | U5: =VLOOKUP(Table1[[#This Row],[Nombres de Centros Educativos (MEDUCA)]],BD_Meduca!A10:N64,11,FALSE) -> NO | V5: =VLOOKUP(Table1[[#This Row],[Nombres de Centros Educativos (MEDUCA)]],BD_Meduca!A10:N64,14,FALSE) -> PREESCOLAR-PRIMARIA | W5: C.E.B.G. BILINGÜE MARIANO THOMAS
A6: 1 | B6: 11 | C6: Escuela Nuevo Paraíso | D6: Bocas del Toro | E6: Almirante | F6: Puerto Almirante | G6: FO | H6: 9.283946 | I6: -82.410794 | J6: 42915 | K6: =(TODAY()-Table1[[#This Row],[Fecha de Activación]])/365 -> 8.460274 | L6: =VLOOKUP(Table1[[#This Row],[Nombre (Punto de Acceso)]],BD_DataTransferida!A33:G86,7,FALSE) -> 165 | M6: =VLOOKUP(Table1[[#This Row],[Nombre (Punto de Acceso)]],BD_Sesiones!A32:I86,7,FALSE) -> 753 | N6: =TRUNC(Table1[[#This Row],[Datos (GB)]]/Table1[[#This Row],[Cantidad de Sesiones]]*1024) -> 224 | O6: =VLOOKUP(Table1[[#This Row],[Nombre (Punto de Acceso)]],BD_Sesiones!A32:I86,8,FALSE) -> C&W Panamá | P6: =VLOOKUP(Table1[[#This Row],[Nombre (Punto de Acceso)]],BD_Sesiones!A32:I86,9,FALSE) -> Sí | Q6: ESC. NUEVO PARAISO | R6: =VLOOKUP(Table1[[#This Row],[Nombres de Centros Educativos (MEDUCA)]],BD_Meduca!A9:N62,9,FALSE) -> OFICIAL | S6: =VLOOKUP(Table1[[#This Row],[Nombres de Centros Educativos (MEDUCA)]],BD_Meduca!A9:N62,10,FALSE) -> ACTIVA | T6: =VLOOKUP(Table1[[#This Row],[Nombres de Centros Educativos (MEDUCA)]],BD_Meduca!A11:N65,7,FALSE) -> RURAL | U6: =VLOOKUP(Table1[[#This Row],[Nombres de Centros Educativos (MEDUCA)]],BD_Meduca!A11:N65,11,FALSE) -> NO | V6: =VLOOKUP(Table1[[#This Row],[Nombres de Centros Educativos (MEDUCA)]],BD_Meduca!A11:N65,14,FALSE) -> PREESCOLAR-PRIMARIA-PREMEDIA | W6: C.E.B.G. BILINGÜE VALLE DE RISCO
A7: 1 | B7: 34 | C7: Cuartel de Bomberos del Empalme | D7: Bocas del Toro | E7: Changuinola | F7: El Empalme | G7: FO | H7: 9.420845 | I7: -82.52088 | J7: 42913 | K7: =(TODAY()-Table1[[#This Row],[Fecha de Activación]])/365 -> 8.4657534 | L7: =VLOOKUP(Table1[[#This Row],[Nombre (Punto de Acceso)]],BD_DataTransferida!A15:G68,7,FALSE) -> 158 | M7: =VLOOKUP(Table1[[#This Row],[Nombre (Punto de Acceso)]],BD_Sesiones!A14:I68,7,FALSE) -> 788 | N7: =TRUNC(Table1[[#This Row],[Datos (GB)]]/Table1[[#This Row],[Cantidad de Sesiones]]*1024) -> 205 | O7: =VLOOKUP(Table1[[#This Row],[Nombre (Punto de Acceso)]],BD_Sesiones!A14:I68,8,FALSE) -> C&W Panamá | P7: =VLOOKUP(Table1[[#This Row],[Nombre (Punto de Acceso)]],BD_Sesiones!A14:I68,9,FALSE) -> Sí | W7: C.E.B.G. LA GLORIA
A8: 1 | B8: 1380 | C8: CEBG Nievecita | D8: Bocas del Toro | E8: Changuinola | F8: Las Tablas | G8: FO | H8: 9.543161 | I8: -82.739405 | J8: 43088 | K8: =(TODAY()-Table1[[#This Row],[Fecha de Activación]])/365 -> 7.9863014 | L8: =VLOOKUP(Table1[[#This Row],[Nombre (Punto de Acceso)]],BD_DataTransferida!A11:G64,7,FALSE) -> 727 | M8: =VLOOKUP(Table1[[#This Row],[Nombre (Punto de Acceso)]],BD_Sesiones!A10:I64,7,FALSE) -> 3780 | N8: =TRUNC(Table1[[#This Row],[Datos (GB)]]/Table1[[#This Row],[Cantidad de Sesiones]]*1024) -> 196 | O8: =VLOOKUP(Table1[[#This Row],[Nombre (Punto de Acceso)]],BD_Sesiones!A10:I64,8,FALSE) -> C&W Panamá | P8: =VLOOKUP(Table1[[#This Row],[Nombre (Punto de Acceso)]],BD_Sesiones!A10:I64,9,FALSE) -> Sí | Q8: C.E.B.G. BILINGÜE NIEVECITA | R8: OFICIAL | S8: ACTIVA | T8: RURAL | U8: NO | V8: PREESCOLAR-PRIMARIA-PREMEDIA | W8: C.E.B.G. LA MINA
A9: 1 | B9: 52 | C9: I.P.T. Chiriquí Grande | D9: Bocas del Toro | E9: Chiriquí Grande | F9: Chiriquí Grande | G9: FO | H9: 8.918024 | I9: -82.184955 | J9: 42950 | K9: =(TODAY()-Table1[[#This Row],[Fecha de Activación]])/365 -> 8.3643836 | L9: =VLOOKUP(Table1[[#This Row],[Nombre (Punto de Acceso)]],BD_DataTransferida!A40:G93,7,FALSE) -> 312 | M9: =VLOOKUP(Table1[[#This Row],[Nombre (Punto de Acceso)]],BD_Sesiones!A39:I93,7,FALSE) -> 1627 | N9: =TRUNC(Table1[[#This Row],[Datos (GB)]]/Table1[[#This Row],[Cantidad de Sesiones]]*1024) -> 196 | O9: =VLOOKUP(Table1[[#This Row],[Nombre (Punto de Acceso)]],BD_Sesiones!A39:I93,8,FALSE) -> C&W Panamá | P9: =VLOOKUP(Table1[[#This Row],[Nombre (Punto de Acceso)]],BD_Sesiones!A39:I93,9,FALSE) -> Sí | Q9: I.P.T. CHIRIQUI GRANDE | R9: =VLOOKUP(Table1[[#This Row],[Nombres de Centros Educativos (MEDUCA)]],BD_Meduca!A11:N69,9,FALSE) -> OFICIAL | S9: =VLOOKUP(Table1[[#This Row],[Nombres de Centros Educativos (MEDUCA)]],BD_Meduca!A11:N69,10,FALSE) -> ACTIVA | T9: =VLOOKUP(Table1[[#This Row],[Nombres de Centros Educativos (MEDUCA)]],BD_Meduca!A11:N72,7,FALSE) -> INDIGENA | U9: =VLOOKUP(Table1[[#This Row],[Nombres de Centros Educativos (MEDUCA)]],BD_Meduca!A11:N72,11,FALSE) -> SI | V9: =VLOOKUP(Table1[[#This Row],[Nombres de Centros Educativos (MEDUCA)]],BD_Meduca!A11:N72,14,FALSE) -> PREESCOLAR-PRIMARIA-PREMEDIA | W9: C.E.B.G. LAS PIÑAS | Y9: TABLA DE RESULTADOS | AE9: Datos para las Gráficas
A10: 1 | B10: 46 | C10: Escuela Finca Débora | D10: Bocas del Toro | E10: Changuinola | F10: Guabito | G10: FO | H10: 9.514801 | I10: -82.594971 | J10: 42950 | K10: =(TODAY()-Table1[[#This Row],[Fecha de Activación]])/365 -> 8.3643836 | L10: =VLOOKUP(Table1[[#This Row],[Nombre (Punto de Acceso)]],BD_DataTransferida!A31:G84,7,FALSE) -> 672 | M10: =VLOOKUP(Table1[[#This Row],[Nombre (Punto de Acceso)]],BD_Sesiones!A30:I84,7,FALSE) -> 3726 | N10: =TRUNC(Table1[[#This Row],[Datos (GB)]]/Table1[[#This Row],[Cantidad de Sesiones]]*1024) -> 184 | O10: =VLOOKUP(Table1[[#This Row],[Nombre (Punto de Acceso)]],BD_Sesiones!A30:I84,8,FALSE) -> C&W Panamá | P10: =VLOOKUP(Table1[[#This Row],[Nombre (Punto de Acceso)]],BD_Sesiones!A30:I84,9,FALSE) -> Sí | W10: C.E.B.G. NANCE DE RISCO | Y10: Distritos y sus Centros Educativos | Z10: Puntos de Acceso | AA10: Datos Consumidos (GB) | AB10: Sesiones | AC10: Avg. de Datos Consumidos por Sesión (MB) | AE10: Distritos | AF10: Datos Consumidos (GB)
A11: 1 | B11: 8 | C11: Escuela Barriada Guaymi | D11: Bocas del Toro | E11: Almirante | F11: Puerto Almirante | G11: FO | H11: 8.242676 | I11: -81.670066 | J11: 42916 | K11: =(TODAY()-Table1[[#This Row],[Fecha de Activación]])/365 -> 8.4575342 | L11: =VLOOKUP(Table1[[#This Row],[Nombre (Punto de Acceso)]],BD_DataTransferida!A17:G70,7,FALSE) -> 159 | M11: =VLOOKUP(Table1[[#This Row],[Nombre (Punto de Acceso)]],BD_Sesiones!A16:I70,7,FALSE) -> 994 | N11: =TRUNC(Table1[[#This Row],[Datos (GB)]]/Table1[[#This Row],[Cantidad de Sesiones]]*1024) -> 163 | O11: =VLOOKUP(Table1[[#This Row],[Nombre (Punto de Acceso)]],BD_Sesiones!A16:I70,8,FALSE) -> C&W Panamá | P11: =VLOOKUP(Table1[[#This Row],[Nombre (Punto de Acceso)]],BD_Sesiones!A16:I70,9,FALSE) -> Sí | Q11: ESC. BARRIADA GUAYMI | R11: =VLOOKUP(Table1[[#This Row],[Nombres de Centros Educativos (MEDUCA)]],BD_Meduca!A8:N46,9,FALSE) -> OFICIAL | S11: =VLOOKUP(Table1[[#This Row],[Nombres de Centros Educativos (MEDUCA)]],BD_Meduca!A8:N46,10,FALSE) -> ACTIVA | T11: =VLOOKUP(Table1[[#This Row],[Nombres de Centros Educativos (MEDUCA)]],BD_Meduca!A8:N49,7,FALSE) -> URBANA | U11: =VLOOKUP(Table1[[#This Row],[Nombres de Centros Educativos (MEDUCA)]],BD_Meduca!A8:N49,11,FALSE) -> NO | V11: =VLOOKUP(Table1[[#This Row],[Nombres de Centros Educativos (MEDUCA)]],BD_Meduca!A8:N49,14,FALSE) -> PREMEDIA | W11: C.E.B.G. QUEBRADA PASTOR | Y11: Almirante | Z11: 6 | AA11: 1228 | AB11: 8474 | AC11: 148 | AE11: Changuinola | AF11: 8418
A12: 1 | B12: 56 | C12: Escuela Cañazas | D12: Bocas del Toro | E12: Chiriquí Grande | F12: Punta Peña | G12: FO | H12: 8.807906 | I12: -82.184109 | J12: 42916 | K12: =(TODAY()-Table1[[#This Row],[Fecha de Activación]])/365 -> 8.4575342 | L12: =VLOOKUP(Table1[[#This Row],[Nombre (Punto de Acceso)]],BD_DataTransferida!A19:G72,7,FALSE) -> 443 | M12: =VLOOKUP(Table1[[#This Row],[Nombre (Punto de Acceso)]],BD_Sesiones!A18:I72,7,FALSE) -> 2980 | N12: =TRUNC(Table1[[#This Row],[Datos (GB)]]/Table1[[#This Row],[Cantidad de Sesiones]]*1024) -> 152 | O12: =VLOOKUP(Table1[[#This Row],[Nombre (Punto de Acceso)]],BD_Sesiones!A18:I72,8,FALSE) -> C&W Panamá | P12: =VLOOKUP(Table1[[#This Row],[Nombre (Punto de Acceso)]],BD_Sesiones!A18:I72,9,FALSE) -> Sí | Q12: ESC. BILINGÜE CAÑAZAS | R12: =VLOOKUP(Table1[[#This Row],[Nombres de Centros Educativos (MEDUCA)]],BD_Meduca!A8:N48,9,FALSE) -> OFICIAL | S12: =VLOOKUP(Table1[[#This Row],[Nombres de Centros Educativos (MEDUCA)]],BD_Meduca!A8:N48,10,FALSE) -> ACTIVA | T12: =VLOOKUP(Table1[[#This Row],[Nombres de Centros Educativos (MEDUCA)]],BD_Meduca!A8:N51,7,FALSE) -> RURAL | U12: =VLOOKUP(Table1[[#This Row],[Nombres de Centros Educativos (MEDUCA)]],BD_Meduca!A8:N51,11,FALSE) -> NO | V12: =VLOOKUP(Table1[[#This Row],[Nombres de Centros Educativos (MEDUCA)]],BD_Meduca!A8:N51,14,FALSE) -> PREMEDIA-MEDIA ACADÉMICA-MEDIA PROFESIONAL Y TÉCNICA | W12: C.E.B.G. SANTA MARTA ABAJO | Y12: COLEGIO SECUNDARIO DE ALMIRANTE | Z12: 1 | AA12: 120 | AB12: 1993 | AC12: 61 | AE12: Chiriquí Grande | AF12: 2126
A13: 1 | B13: 55 | C13: C.E.B.G. PUNTA PEÑA | D13: Bocas del Toro | E13: Chiriquí Grande | F13: Punta Peña | G13: FO | H13: 8.913516 | I13: -82.186711 | J13: 42914 | K13: =(TODAY()-Table1[[#This Row],[Fecha de Activación]])/365 -> 8.4630137 | L13: =VLOOKUP(Table1[[#This Row],[Nombre (Punto de Acceso)]],BD_DataTransferida!A10:G63,7,FALSE) -> 407 | M13: =VLOOKUP(Table1[[#This Row],[Nombre (Punto de Acceso)]],BD_Sesiones!A9:I63,7,FALSE) -> 2928 | N13: =TRUNC(Table1[[#This Row],[Datos (GB)]]/Table1[[#This Row],[Cantidad de Sesiones]]*1024) -> 142 | O13: =VLOOKUP(Table1[[#This Row],[Nombre (Punto de Acceso)]],BD_Sesiones!A9:I63,8,FALSE) -> C&W Panamá | P13: =VLOOKUP(Table1[[#This Row],[Nombre (Punto de Acceso)]],BD_Sesiones!A9:I63,9,FALSE) -> Sí | Q13: C.E.B.G. PUNTA PEÑA | R13: =VLOOKUP(Table1[[#This Row],[Nombres de Centros Educativos (MEDUCA)]],BD_Meduca!A7:N39,9,FALSE) -> OFICIAL | S13: =VLOOKUP(Table1[[#This Row],[Nombres de Centros Educativos (MEDUCA)]],BD_Meduca!A7:N39,10,FALSE) -> ACTIVA | T13: =VLOOKUP(Table1[[#This Row],[Nombres de Centros Educativos (MEDUCA)]],BD_Meduca!A7:N42,7,FALSE) -> INDIGENA | U13: =VLOOKUP(Table1[[#This Row],[Nombres de Centros Educativos (MEDUCA)]],BD_Meduca!A7:N42,11,FALSE) -> SI | V13: =VLOOKUP(Table1[[#This Row],[Nombres de Centros Educativos (MEDUCA)]],BD_Meduca!A7:N42,14,FALSE) -> PREESCOLAR-PRIMARIA-PREMEDIA-MEDIA PROFESIONAL Y TÉCNICA | W13: C.E.B.G. SIEYICK | Y13: ESC. ALMIRANTE | Z13: 1 | AA13: 53 | AB13: 1259 | AC13: 43 | AE13: Almirante | AF13: 1228
A14: 1 | B14: 1582 | C14: MIDES Changuinola | D14: Bocas del Toro | E14: Changuinola | F14: Changuinola | G14: PTP | H14: 9.45056 | I14: -82.52094 | J14: 43621 | K14: =(TODAY()-Table1[[#This Row],[Fecha de Activación]])/365 -> 6.5260274 | L14: =VLOOKUP(Table1[[#This Row],[Nombre (Punto de Acceso)]],BD_DataTransferida!A43:G96,7,FALSE) -> 143 | M14: =VLOOKUP(Table1[[#This Row],[Nombre (Punto de Acceso)]],BD_Sesiones!A42:I96,7,FALSE) -> 1032 | N14: =TRUNC(Table1[[#This Row],[Datos (GB)]]/Table1[[#This Row],[Cantidad de Sesiones]]*1024) -> 141 | O14: =VLOOKUP(Table1[[#This Row],[Nombre (Punto de Acceso)]],BD_Sesiones!A42:I96,8,FALSE) -> C&W Panamá | P14: =VLOOKUP(Table1[[#This Row],[Nombre (Punto de Acceso)]],BD_Sesiones!A42:I96,9,FALSE) -> Sí | W14: C.E.B.G. TRES PIEDRAS | Y14: ESC. BARRIADA GUAYMI | Z14: 1 | AA14: 159 | AB14: 994 | AC14: 163 | AE14: Bocas del Toro | AF14: 382
A15: 1 | B15: 44 | C15: Escuela Finca 41 Guabito | D15: Bocas del Toro | E15: Changuinola | F15: Guabito | G15: FO | H15: 9.491225 | I15: -82.624136 | J15: 42927 | K15: =(TODAY()-Table1[[#This Row],[Fecha de Activación]])/365 -> 8.4273973 | L15: =VLOOKUP(Table1[[#This Row],[Nombre (Punto de Acceso)]],BD_DataTransferida!A24:G77,7,FALSE) -> 133 | M15: =VLOOKUP(Table1[[#This Row],[Nombre (Punto de Acceso)]],BD_Sesiones!A23:I77,7,FALSE) -> 996 | N15: =TRUNC(Table1[[#This Row],[Datos (GB)]]/Table1[[#This Row],[Cantidad de Sesiones]]*1024) -> 136 | O15: =VLOOKUP(Table1[[#This Row],[Nombre (Punto de Acceso)]],BD_Sesiones!A23:I77,8,FALSE) -> C&W Panamá | P15: =VLOOKUP(Table1[[#This Row],[Nombre (Punto de Acceso)]],BD_Sesiones!A23:I77,9,FALSE) -> Sí | Q15: ESC. FINCA 41 ANEXA GUABITO | R15: =VLOOKUP(Table1[[#This Row],[Nombres de Centros Educativos (MEDUCA)]],BD_Meduca!A8:N53,9,FALSE) -> OFICIAL | S15: =VLOOKUP(Table1[[#This Row],[Nombres de Centros Educativos (MEDUCA)]],BD_Meduca!A8:N53,10,FALSE) -> ACTIVA | T15: =VLOOKUP(Table1[[#This Row],[Nombres de Centros Educativos (MEDUCA)]],BD_Meduca!A8:N56,7,FALSE) -> INDIGENA | U15: =VLOOKUP(Table1[[#This Row],[Nombres de Centros Educativos (MEDUCA)]],BD_Meduca!A8:N56,11,FALSE) -> SI | V15: =VLOOKUP(Table1[[#This Row],[Nombres de Centros Educativos (MEDUCA)]],BD_Meduca!A8:N56,14,FALSE) -> PREESCOLAR-PRIMARIA | W15: CAIPI MIS PRIMEROS PASOS DE TEOBROMA | Y15: ESC. BILINGÜE BERTA LOPEZ | Z15: 1 | AA15: 139 | AB15: 1111 | AC15: 128 | AE15: Grand Total | AF15: 12154
A16: 1 | B16: 48 | C16: Escuela San San Medio (Anexa) | D16: Bocas del Toro | E16: Changuinola | F16: Guabito | G16: FO | H16: 9.464957 | I16: -82.549523 | J16: 42914 | K16: =(TODAY()-Table1[[#This Row],[Fecha de Activación]])/365 -> 8.4630137 | L16: =VLOOKUP(Table1[[#This Row],[Nombre (Punto de Acceso)]],BD_DataTransferida!A36:G89,7,FALSE) -> 325 | M16: =VLOOKUP(Table1[[#This Row],[Nombre (Punto de Acceso)]],BD_Sesiones!A35:I89,7,FALSE) -> 2487 | N16: =TRUNC(Table1[[#This Row],[Datos (GB)]]/Table1[[#This Row],[Cantidad de Sesiones]]*1024) -> 133 | O16: =VLOOKUP(Table1[[#This Row],[Nombre (Punto de Acceso)]],BD_Sesiones!A35:I89,8,FALSE) -> C&W Panamá | P16: =VLOOKUP(Table1[[#This Row],[Nombre (Punto de Acceso)]],BD_Sesiones!A35:I89,9,FALSE) -> Sí | Q16: ESC. SAN SAN MEDIO ANEXA | R16: =VLOOKUP(Table1[[#This Row],[Nombres de Centros Educativos (MEDUCA)]],BD_Meduca!A11:N65,9,FALSE) -> OFICIAL | S16: =VLOOKUP(Table1[[#This Row],[Nombres de Centros Educativos (MEDUCA)]],BD_Meduca!A11:N65,10,FALSE) -> ACTIVA | T16: =VLOOKUP(Table1[[#This Row],[Nombres de Centros Educativos (MEDUCA)]],BD_Meduca!A11:N68,7,FALSE) -> RURAL | U16: =VLOOKUP(Table1[[#This Row],[Nombres de Centros Educativos (MEDUCA)]],BD_Meduca!A11:N68,11,FALSE) -> NO | V16: =VLOOKUP(Table1[[#This Row],[Nombres de Centros Educativos (MEDUCA)]],BD_Meduca!A11:N68,14,FALSE) -> PRIMARIA | W16: CENTRO DE ESTUDIOS SUPERIORES DE BELLAS ARTES Y FOLKLORE DE CHANGUINOLA | Y16: ESC. MIRAFLORES | Z16: 1 | AA16: 592 | AB16: 2364 | AC16: 256
A17: 1 | B17: 51 | C17: C.E.B.G. Dionisia G. de Ayarza | D17: Bocas del Toro | E17: Chiriquí Grande | F17: Chiriquí Grande | G17: FO | H17: 8.945522 | I17: -82.115149 | J17: 42950 | K17: =(TODAY()-Table1[[#This Row],[Fecha de Activación]])/365 -> 8.3643836 | L17: =VLOOKUP(Table1[[#This Row],[Nombre (Punto de Acceso)]],BD_DataTransferida!A5:G58,7,FALSE) -> 139 | M17: =VLOOKUP(Table1[[#This Row],[Nombre (Punto de Acceso)]],BD_Sesiones!A4:I58,7,FALSE) -> 1098 | N17: =TRUNC(Table1[[#This Row],[Datos (GB)]]/Table1[[#This Row],[Cantidad de Sesiones]]*1024) -> 129 | O17: =VLOOKUP(Table1[[#This Row],[Nombre (Punto de Acceso)]],BD_Sesiones!A4:I58,8,FALSE) -> C&W Panamá | P17: =VLOOKUP(Table1[[#This Row],[Nombre (Punto de Acceso)]],BD_Sesiones!A4:I58,9,FALSE) -> Sí | Q17: ESC. BILINGÜE DIONISIA G. DE AYARZA | R17: =VLOOKUP(Table1[[#This Row],[Nombres de Centros Educativos (MEDUCA)]],BD_Meduca!A3:N34,9,FALSE) -> OFICIAL | S17: =VLOOKUP(Table1[[#This Row],[Nombres de Centros Educativos (MEDUCA)]],BD_Meduca!A3:N34,10,FALSE) -> ACTIVA | T17: =VLOOKUP(Table1[[#This Row],[Nombres de Centros Educativos (MEDUCA)]],BD_Meduca!A5:N37,7,FALSE) -> RURAL | U17: =VLOOKUP(Table1[[#This Row],[Nombres de Centros Educativos (MEDUCA)]],BD_Meduca!A5:N37,11,FALSE) -> NO | V17: =VLOOKUP(Table1[[#This Row],[Nombres de Centros Educativos (MEDUCA)]],BD_Meduca!A5:N37,14,FALSE) -> PREMEDIA-MEDIA ACADÉMICA | W17: CENTRO EDUCATIVO LUIS AMIGÓ | Y17: ESC. NUEVO PARAISO | Z17: 1 | AA17: 165 | AB17: 753 | AC17: 224 | AE17: Distritos | AF17: # de Sesiones
A18: 1 | B18: 9 | C18: Escuela Berta López | D18: Bocas del Toro | E18: Almirante | F18: Puerto Almirante | G18: FO | H18: 9.29509 | I18: -82.404895 | J18: 42915 | K18: =(TODAY()-Table1[[#This Row],[Fecha de Activación]])/365 -> 8.460274 | L18: =VLOOKUP(Table1[[#This Row],[Nombre (Punto de Acceso)]],BD_DataTransferida!A18:G71,7,FALSE) -> 139 | M18: =VLOOKUP(Table1[[#This Row],[Nombre (Punto de Acceso)]],BD_Sesiones!A17:I71,7,FALSE) -> 1111 | N18: =TRUNC(Table1[[#This Row],[Datos (GB)]]/Table1[[#This Row],[Cantidad de Sesiones]]*1024) -> 128 | O18: =VLOOKUP(Table1[[#This Row],[Nombre (Punto de Acceso)]],BD_Sesiones!A17:I71,8,FALSE) -> C&W Panamá | P18: =VLOOKUP(Table1[[#This Row],[Nombre (Punto de Acceso)]],BD_Sesiones!A17:I71,9,FALSE) -> Sí | Q18: ESC. BILINGÜE BERTA LOPEZ | R18: =VLOOKUP(Table1[[#This Row],[Nombres de Centros Educativos (MEDUCA)]],BD_Meduca!A8:N47,9,FALSE) -> PARTICULAR | S18: =VLOOKUP(Table1[[#This Row],[Nombres de Centros Educativos (MEDUCA)]],BD_Meduca!A8:N47,10,FALSE) -> ACTIVA | T18: =VLOOKUP(Table1[[#This Row],[Nombres de Centros Educativos (MEDUCA)]],BD_Meduca!A8:N50,7,FALSE) -> URBANA | U18: =VLOOKUP(Table1[[#This Row],[Nombres de Centros Educativos (MEDUCA)]],BD_Meduca!A8:N50,11,FALSE) -> NO | V18: =VLOOKUP(Table1[[#This Row],[Nombres de Centros Educativos (MEDUCA)]],BD_Meduca!A8:N50,14,FALSE) -> PREMEDIA- MEDIA | W18: CENTRO EDUCATIVO OFICIAL NOCTURNO DE ALMIRANTE | Y18: Bocas del Toro | Z18: 6 | AA18: 382 | AB18: 5733 | AC18: 68 | AE18: Changuinola | AF18: 92859
A19: 1 | B19: 36 | C19: Escuela El Silencio | D19: Bocas del Toro | E19: Changuinola | F19: El Empalme | G19: FO | H19: 9.388555 | I19: -82.531266 | J19: 42913 | K19: =(TODAY()-Table1[[#This Row],[Fecha de Activación]])/365 -> 8.4657534 | L19: =VLOOKUP(Table1[[#This Row],[Nombre (Punto de Acceso)]],BD_DataTransferida!A21:G74,7,FALSE) -> 210 | M19: =VLOOKUP(Table1[[#This Row],[Nombre (Punto de Acceso)]],BD_Sesiones!A20:I74,7,FALSE) -> 1775 | N19: =TRUNC(Table1[[#This Row],[Datos (GB)]]/Table1[[#This Row],[Cantidad de Sesiones]]*1024) -> 121 | O19: =VLOOKUP(Table1[[#This Row],[Nombre (Punto de Acceso)]],BD_Sesiones!A20:I74,8,FALSE) -> C&W Panamá | P19: =VLOOKUP(Table1[[#This Row],[Nombre (Punto de Acceso)]],BD_Sesiones!A20:I74,9,FALSE) -> Sí | Q19: ESC. BILINGÜE EL SILENCIO | R19: =VLOOKUP(Table1[[#This Row],[Nombres de Centros Educativos (MEDUCA)]],BD_Meduca!A8:N50,9,FALSE) -> OFICIAL | S19: =VLOOKUP(Table1[[#This Row],[Nombres de Centros Educativos (MEDUCA)]],BD_Meduca!A8:N50,10,FALSE) -> ACTIVA | T19: =VLOOKUP(Table1[[#This Row],[Nombres de Centros Educativos (MEDUCA)]],BD_Meduca!A8:N53,7,FALSE) -> INDIGENA | U19: =VLOOKUP(Table1[[#This Row],[Nombres de Centros Educativos (MEDUCA)]],BD_Meduca!A8:N53,11,FALSE) -> SI | V19: =VLOOKUP(Table1[[#This Row],[Nombres de Centros Educativos (MEDUCA)]],BD_Meduca!A8:N53,14,FALSE) -> PREESCOLAR-PRIMARIA | W19: CENTRO LABORAL NOCTURNO CHIRIQUI GRANDE (ESNOCH) | Y19: COLEGIO ROGELIO JOSUÉ IBARRA | Z19: 1 | AA19: 39 | AB19: 453 | AC19: 88 | AE19: Chiriquí Grande | AF19: 19448
A20: 1 | B20: 43 | C20: Colegio Secundario de Guabito | D20: Bocas del Toro | E20: Changuinola | F20: Guabito | G20: FO | H20: 9.488559 | I20: -82.60768 | J20: 42927 | K20: =(TODAY()-Table1[[#This Row],[Fecha de Activación]])/365 -> 8.4273973 | L20: =VLOOKUP(Table1[[#This Row],[Nombre (Punto de Acceso)]],BD_DataTransferida!A14:G67,7,FALSE) -> 276 | M20: =VLOOKUP(Table1[[#This Row],[Nombre (Punto de Acceso)]],BD_Sesiones!A13:I67,7,FALSE) -> 2403 | N20: =TRUNC(Table1[[#This Row],[Datos (GB)]]/Table1[[#This Row],[Cantidad de Sesiones]]*1024) -> 117 | O20: =VLOOKUP(Table1[[#This Row],[Nombre (Punto de Acceso)]],BD_Sesiones!A13:I67,8,FALSE) -> C&W Panamá | P20: =VLOOKUP(Table1[[#This Row],[Nombre (Punto de Acceso)]],BD_Sesiones!A13:I67,9,FALSE) -> Sí | Q20: COLEGIO SECUNDARIO DE GUABITO | R20: =VLOOKUP(Table1[[#This Row],[Nombres de Centros Educativos (MEDUCA)]],BD_Meduca!A7:N43,9,FALSE) -> OFICIAL | S20: =VLOOKUP(Table1[[#This Row],[Nombres de Centros Educativos (MEDUCA)]],BD_Meduca!A7:N43,10,FALSE) -> ACTIVA | T20: =VLOOKUP(Table1[[#This Row],[Nombres de Centros Educativos (MEDUCA)]],BD_Meduca!A8:N46,7,FALSE) -> RURAL | U20: =VLOOKUP(Table1[[#This Row],[Nombres de Centros Educativos (MEDUCA)]],BD_Meduca!A8:N46,11,FALSE) -> NO | V20: =VLOOKUP(Table1[[#This Row],[Nombres de Centros Educativos (MEDUCA)]],BD_Meduca!A8:N46,14,FALSE) -> PRIMARIA | W20: CENTRO OFICIAL NOCTURNO DE GUABITO | Y20: ESC. BILINGÜE REPUBLICA DE NICARAGUA | Z20: 1 | AA20: 24 | AB20: 1097 | AC20: 22 | AE20: Almirante | AF20: 8474
A21: 1 | B21: 45 | C21: Escuela Finca 54 | D21: Bocas del Toro | E21: Changuinola | F21: Guabito | G21: FO | H21: 9.495357 | I21: -82.586637 | J21: 42927 | K21: =(TODAY()-Table1[[#This Row],[Fecha de Activación]])/365 -> 8.4273973 | L21: =VLOOKUP(Table1[[#This Row],[Nombre (Punto de Acceso)]],BD_DataTransferida!A27:G80,7,FALSE) -> 202 | M21: =VLOOKUP(Table1[[#This Row],[Nombre (Punto de Acceso)]],BD_Sesiones!A26:I80,7,FALSE) -> 1776 | N21: =TRUNC(Table1[[#This Row],[Datos (GB)]]/Table1[[#This Row],[Cantidad de Sesiones]]*1024) -> 116 | O21: =VLOOKUP(Table1[[#This Row],[Nombre (Punto de Acceso)]],BD_Sesiones!A26:I80,8,FALSE) -> C&W Panamá | P21: =VLOOKUP(Table1[[#This Row],[Nombre (Punto de Acceso)]],BD_Sesiones!A26:I80,9,FALSE) -> Sí | Q21: ESC. FINCA 54 | R21: =VLOOKUP(Table1[[#This Row],[Nombres de Centros Educativos (MEDUCA)]],BD_Meduca!A8:N56,9,FALSE) -> OFICIAL | S21: =VLOOKUP(Table1[[#This Row],[Nombres de Centros Educativos (MEDUCA)]],BD_Meduca!A8:N56,10,FALSE) -> ACTIVA | T21: =VLOOKUP(Table1[[#This Row],[Nombres de Centros Educativos (MEDUCA)]],BD_Meduca!A8:N59,7,FALSE) -> URBANA | U21: =VLOOKUP(Table1[[#This Row],[Nombres de Centros Educativos (MEDUCA)]],BD_Meduca!A8:N59,11,FALSE) -> NO | V21: =VLOOKUP(Table1[[#This Row],[Nombres de Centros Educativos (MEDUCA)]],BD_Meduca!A8:N59,14,FALSE) -> PREESCOLAR-PRIMARIA | W21: CENTRO PARTICULAR MULTICULTURAL INTERNATIONAL SCHOOL DR. ANDRÉS CULIOLIS BAYARD (ANTES CENTRO EDUCATIVO EVANGELICO CUADRANGULAR BET-EL, ISLA COLÓN) | Y21: Otras Instituciones | Z21: 4 | AA21: 319 | AB21: 4183 | AC21: 78 | AE21: Bocas del Toro | AF21: 5733
A22: 1 | B22: 32 | C22: Escuela Finca 67 | D22: Bocas del Toro | E22: Changuinola | F22: Changuinola | G22: FO | H22: 9.437948 | I22: -82.497599 | J22: 42949 | K22: =(TODAY()-Table1[[#This Row],[Fecha de Activación]])/365 -> 8.3671233 | L22: =VLOOKUP(Table1[[#This Row],[Nombre (Punto de Acceso)]],BD_DataTransferida!A30:G83,7,FALSE) -> 380 | M22: =VLOOKUP(Table1[[#This Row],[Nombre (Punto de Acceso)]],BD_Sesiones!A29:I83,7,FALSE) -> 3385 | N22: =TRUNC(Table1[[#This Row],[Datos (GB)]]/Table1[[#This Row],[Cantidad de Sesiones]]*1024) -> 114 | O22: =VLOOKUP(Table1[[#This Row],[Nombre (Punto de Acceso)]],BD_Sesiones!A29:I83,8,FALSE) -> C&W Panamá | P22: =VLOOKUP(Table1[[#This Row],[Nombre (Punto de Acceso)]],BD_Sesiones!A29:I83,9,FALSE) -> Sí | Q22: ESC. FINCA 67 | R22: =VLOOKUP(Table1[[#This Row],[Nombres de Centros Educativos (MEDUCA)]],BD_Meduca!A8:N59,9,FALSE) -> OFICIAL | S22: =VLOOKUP(Table1[[#This Row],[Nombres de Centros Educativos (MEDUCA)]],BD_Meduca!A8:N59,10,FALSE) -> ACTIVA | T22: =VLOOKUP(Table1[[#This Row],[Nombres de Centros Educativos (MEDUCA)]],BD_Meduca!A9:N62,7,FALSE) -> URBANA | U22: =VLOOKUP(Table1[[#This Row],[Nombres de Centros Educativos (MEDUCA)]],BD_Meduca!A9:N62,11,FALSE) -> NO | V22: =VLOOKUP(Table1[[#This Row],[Nombres de Centros Educativos (MEDUCA)]],BD_Meduca!A9:N62,14,FALSE) -> PREMEDIA-MEDIA ACADÉMICA-MEDIA PROFESIONAL Y TÉCNICA | W22: COIF ESTADO DE ISRAEL | Y22: Changuinola | Z22: 35 | AA22: 8418 | AB22: 92859 | AC22: 92 | AE22: Grand Total | AF22: 126514
A23: 1 | B23: 1440 | C23: HOSPITAL DE CHIRIQUI GRANDE | D23: Bocas del Toro | E23: Chiriquí Grande | F23: Rambala | G23: FO | H23: 8.930188 | I23: -82.182191 | J23: 43361 | K23: =(TODAY()-Table1[[#This Row],[Fecha de Activación]])/365 -> 7.2383562 | L23: =VLOOKUP(Table1[[#This Row],[Nombre (Punto de Acceso)]],BD_DataTransferida!A38:G91,7,FALSE) -> 294 | M23: =VLOOKUP(Table1[[#This Row],[Nombre (Punto de Acceso)]],BD_Sesiones!A37:I91,7,FALSE) -> 2754 | N23: =TRUNC(Table1[[#This Row],[Datos (GB)]]/Table1[[#This Row],[Cantidad de Sesiones]]*1024) -> 109 | O23: =VLOOKUP(Table1[[#This Row],[Nombre (Punto de Acceso)]],BD_Sesiones!A37:I91,8,FALSE) -> C&W Panamá | P23: =VLOOKUP(Table1[[#This Row],[Nombre (Punto de Acceso)]],BD_Sesiones!A37:I91,9,FALSE) -> Sí | W23: COIF FROEBELIN | Y23: C.E.B.G. BILINGÜE NIEVECITA | Z23: 1 | AA23: 727 | AB23: 3780 | AC23: 196
A24: 1 | B24: 22 | C24: Parque de la escuela de changuinola | D24: Bocas del Toro | E24: Changuinola | F24: Changuinola | G24: FO | H24: 9.456052 | I24: -82.514567 | J24: 42927 | K24: =(TODAY()-Table1[[#This Row],[Fecha de Activación]])/365 -> 8.4273973 | L24: =VLOOKUP(Table1[[#This Row],[Nombre (Punto de Acceso)]],BD_DataTransferida!A46:G99,7,FALSE) -> 155 | M24: =VLOOKUP(Table1[[#This Row],[Nombre (Punto de Acceso)]],BD_Sesiones!A45:I99,7,FALSE) -> 1581 | N24: =TRUNC(Table1[[#This Row],[Datos (GB)]]/Table1[[#This Row],[Cantidad de Sesiones]]*1024) -> 100 | O24: =VLOOKUP(Table1[[#This Row],[Nombre (Punto de Acceso)]],BD_Sesiones!A45:I99,8,FALSE) -> C&W Panamá | P24: =VLOOKUP(Table1[[#This Row],[Nombre (Punto de Acceso)]],BD_Sesiones!A45:I99,9,FALSE) -> Sí | W24: COLEGIO ADVENTISTA BILINGÜE DE CHANGUINOLA | Y24: C.E.B.G. BILINGÜE EL EMPALME | Z24: 1 | AA24: 128 | AB24: 2444 | AC24: 53
A25: 1 | B25: 49 | C25: Policlínica de Guabito CSS | D25: Bocas del Toro | E25: Changuinola | F25: Guabito | G25: FO | H25: 9.49632 | I25: -82.610203 | J25: 42914 | K25: =(TODAY()-Table1[[#This Row],[Fecha de Activación]])/365 -> 8.4630137 | L25: =VLOOKUP(Table1[[#This Row],[Nombre (Punto de Acceso)]],BD_DataTransferida!A51:G104,7,FALSE) -> 335 | M25: =VLOOKUP(Table1[[#This Row],[Nombre (Punto de Acceso)]],BD_Sesiones!A50:I104,7,FALSE) -> 3484 | N25: =TRUNC(Table1[[#This Row],[Datos (GB)]]/Table1[[#This Row],[Cantidad de Sesiones]]*1024) -> 98 | O25: =VLOOKUP(Table1[[#This Row],[Nombre (Punto de Acceso)]],BD_Sesiones!A50:I104,8,FALSE) -> C&W Panamá | P25: =VLOOKUP(Table1[[#This Row],[Nombre (Punto de Acceso)]],BD_Sesiones!A50:I104,9,FALSE) -> Sí | W25: COLEGIO SAN MARCOS | Y25: C.E.B.G. BILINGÜE FINCA 04 | Z25: 1 | AA25: 137 | AB25: 2157 | AC25: 65
A26: 1 | B26: 41 | C26: UTP El Empalme | D26: Bocas del Toro | E26: Changuinola | F26: El Empalme | G26: FO | H26: 9.421975 | I26: -82.523321 | J26: 42913 | K26: =(TODAY()-Table1[[#This Row],[Fecha de Activación]])/365 -> 8.4657534 | L26: =VLOOKUP(Table1[[#This Row],[Nombre (Punto de Acceso)]],BD_DataTransferida!A55:G108,7,FALSE) -> 144 | M26: =VLOOKUP(Table1[[#This Row],[Nombre (Punto de Acceso)]],BD_Sesiones!A54:I108,7,FALSE) -> 1503 | N26: =TRUNC(Table1[[#This Row],[Datos (GB)]]/Table1[[#This Row],[Cantidad de Sesiones]]*1024) -> 98 | O26: =VLOOKUP(Table1[[#This Row],[Nombre (Punto de Acceso)]],BD_Sesiones!A54:I108,8,FALSE) -> C&W Panamá | P26: =VLOOKUP(Table1[[#This Row],[Nombre (Punto de Acceso)]],BD_Sesiones!A54:I108,9,FALSE) -> Sí | W26: COLEGIO SECUNDARIO NIEVECITA | Y26: C.E.B.G. BILINGÜE FINCA 62 | Z26: 1 | AA26: 279 | AB26: 4745 | AC26: 60 | AE26: Distritos | AF26: Promedio de Consumo (MB)
A27: 1 | B27: 42 | C27: C.E.B.G. Guabito | D27: Bocas del Toro | E27: Changuinola | F27: Guabito | G27: FO | H27: 9.492023 | I27: -82.611638 | J27: 42927 | K27: =(TODAY()-Table1[[#This Row],[Fecha de Activación]])/365 -> 8.4273973 | L27: =VLOOKUP(Table1[[#This Row],[Nombre (Punto de Acceso)]],BD_DataTransferida!A9:G62,7,FALSE) -> 354 | M27: =VLOOKUP(Table1[[#This Row],[Nombre (Punto de Acceso)]],BD_Sesiones!A8:I62,7,FALSE) -> 3998 | N27: =TRUNC(Table1[[#This Row],[Datos (GB)]]/Table1[[#This Row],[Cantidad de Sesiones]]*1024) -> 90 | O27: =VLOOKUP(Table1[[#This Row],[Nombre (Punto de Acceso)]],BD_Sesiones!A8:I62,8,FALSE) -> C&W Panamá | P27: =VLOOKUP(Table1[[#This Row],[Nombre (Punto de Acceso)]],BD_Sesiones!A8:I62,9,FALSE) -> Sí | Q27: C.E.B.G. BILINGÜE GUABITO | R27: =VLOOKUP(Table1[[#This Row],[Nombres de Centros Educativos (MEDUCA)]],BD_Meduca!A6:N38,9,FALSE) -> OFICIAL | S27: =VLOOKUP(Table1[[#This Row],[Nombres de Centros Educativos (MEDUCA)]],BD_Meduca!A6:N38,10,FALSE) -> ACTIVA | T27: RURAL | U27: NO | V27: PREESCOLAR-PRIMARIA-PREMEDIA | W27: EDJA GUABITO | Y27: C.E.B.G. BILINGÜE GUABITO | Z27: 1 | AA27: 354 | AB27: 3998 | AC27: 90 | AE27: Almirante | AF27: 148
A28: 1 | B28: 1 | C28: Colegio Rogelio Josué Ibarra | D28: Bocas del Toro | E28: Bocas del Toro | F28: Bocas del Toro | G28: FO | H28: 9.340654 | I28: -82.242499 | J28: 42928 | K28: =(TODAY()-Table1[[#This Row],[Fecha de Activación]])/365 -> 8.4246575 | L28: =VLOOKUP(Table1[[#This Row],[Nombre (Punto de Acceso)]],BD_DataTransferida!A13:G66,7,FALSE) -> 39 | M28: =VLOOKUP(Table1[[#This Row],[Nombre (Punto de Acceso)]],BD_Sesiones!A12:I66,7,FALSE) -> 453 | N28: =TRUNC(Table1[[#This Row],[Datos (GB)]]/Table1[[#This Row],[Cantidad de Sesiones]]*1024) -> 88 | O28: =VLOOKUP(Table1[[#This Row],[Nombre (Punto de Acceso)]],BD_Sesiones!A12:I66,8,FALSE) -> C&W Panamá | P28: =VLOOKUP(Table1[[#This Row],[Nombre (Punto de Acceso)]],BD_Sesiones!A12:I66,9,FALSE) -> Sí | Q28: COLEGIO ROGELIO JOSUÉ IBARRA | R28: =VLOOKUP(Table1[[#This Row],[Nombres de Centros Educativos (MEDUCA)]],BD_Meduca!A7:N42,9,FALSE) -> OFICIAL | S28: =VLOOKUP(Table1[[#This Row],[Nombres de Centros Educativos (MEDUCA)]],BD_Meduca!A7:N42,10,FALSE) -> ACTIVA | T28: =VLOOKUP(Table1[[#This Row],[Nombres de Centros Educativos (MEDUCA)]],BD_Meduca!A7:N45,7,FALSE) -> RURAL | U28: =VLOOKUP(Table1[[#This Row],[Nombres de Centros Educativos (MEDUCA)]],BD_Meduca!A7:N45,11,FALSE) -> NO | V28: =VLOOKUP(Table1[[#This Row],[Nombres de Centros Educativos (MEDUCA)]],BD_Meduca!A7:N45,14,FALSE) -> PREESCOLAR-PRIMARIA | W28: EDJA QUEBRADA PINZON | Y28: COLEGIO SECUNDARIO DE GUABITO | Z28: 1 | AA28: 276 | AB28: 2403 | AC28: 117 | AE28: Chiriquí Grande | AF28: 111
A29: 1 | B29: 38 | C29: I.P.T. EL SILENCIO | D29: Bocas del Toro | E29: Changuinola | F29: El Empalme | G29: FO | H29: 9.375363 | I29: -82.528324 | J29: 42913 | K29: =(TODAY()-Table1[[#This Row],[Fecha de Activación]])/365 -> 8.4657534 | L29: =VLOOKUP(Table1[[#This Row],[Nombre (Punto de Acceso)]],BD_DataTransferida!A41:G94,7,FALSE) -> 138 | M29: =VLOOKUP(Table1[[#This Row],[Nombre (Punto de Acceso)]],BD_Sesiones!A40:I94,7,FALSE) -> 1617 | N29: =TRUNC(Table1[[#This Row],[Datos (GB)]]/Table1[[#This Row],[Cantidad de Sesiones]]*1024) -> 87 | O29: =VLOOKUP(Table1[[#This Row],[Nombre (Punto de Acceso)]],BD_Sesiones!A40:I94,8,FALSE) -> C&W Panamá | P29: =VLOOKUP(Table1[[#This Row],[Nombre (Punto de Acceso)]],BD_Sesiones!A40:I94,9,FALSE) -> Sí | Q29: I.P.T. EL SILENCIO | R29: =VLOOKUP(Table1[[#This Row],[Nombres de Centros Educativos (MEDUCA)]],BD_Meduca!A11:N70,9,FALSE) -> OFICIAL | S29: =VLOOKUP(Table1[[#This Row],[Nombres de Centros Educativos (MEDUCA)]],BD_Meduca!A11:N70,10,FALSE) -> ACTIVA | T29: =VLOOKUP(Table1[[#This Row],[Nombres de Centros Educativos (MEDUCA)]],BD_Meduca!A11:N73,7,FALSE) -> RURAL | U29: =VLOOKUP(Table1[[#This Row],[Nombres de Centros Educativos (MEDUCA)]],BD_Meduca!A11:N73,11,FALSE) -> NO | V29: =VLOOKUP(Table1[[#This Row],[Nombres de Centros Educativos (MEDUCA)]],BD_Meduca!A11:N73,14,FALSE) -> PREESCOLAR-PRIMARIA | W29: ESC. BELLA VISTA | Y29: ESC. BILINGÜE FINCA 32 | Z29: 1 | AA29: 224 | AB29: 3301 | AC29: 69 | AE29: Changuinola | AF29: 92
A30: 1 | B30: 29 | C30: Escuela Finca 43 | D30: Bocas del Toro | E30: Changuinola | F30: Changuinola | G30: FO | H30: 9.474736 | I30: -82.499969 | J30: 42912 | K30: =(TODAY()-Table1[[#This Row],[Fecha de Activación]])/365 -> 8.4684932 | L30: =VLOOKUP(Table1[[#This Row],[Nombre (Punto de Acceso)]],BD_DataTransferida!A25:G78,7,FALSE) -> 182 | M30: =VLOOKUP(Table1[[#This Row],[Nombre (Punto de Acceso)]],BD_Sesiones!A24:I78,7,FALSE) -> 2159 | N30: =TRUNC(Table1[[#This Row],[Datos (GB)]]/Table1[[#This Row],[Cantidad de Sesiones]]*1024) -> 86 | O30: =VLOOKUP(Table1[[#This Row],[Nombre (Punto de Acceso)]],BD_Sesiones!A24:I78,8,FALSE) -> C&W Panamá | P30: =VLOOKUP(Table1[[#This Row],[Nombre (Punto de Acceso)]],BD_Sesiones!A24:I78,9,FALSE) -> Sí | Q30: ESC. FINCA 43 | R30: =VLOOKUP(Table1[[#This Row],[Nombres de Centros Educativos (MEDUCA)]],BD_Meduca!A8:N54,9,FALSE) -> OFICIAL | S30: =VLOOKUP(Table1[[#This Row],[Nombres de Centros Educativos (MEDUCA)]],BD_Meduca!A8:N54,10,FALSE) -> ACTIVA | T30: =VLOOKUP(Table1[[#This Row],[Nombres de Centros Educativos (MEDUCA)]],BD_Meduca!A8:N57,7,FALSE) -> INDIGENA | U30: =VLOOKUP(Table1[[#This Row],[Nombres de Centros Educativos (MEDUCA)]],BD_Meduca!A8:N57,11,FALSE) -> SI | V30: =VLOOKUP(Table1[[#This Row],[Nombres de Centros Educativos (MEDUCA)]],BD_Meduca!A8:N57,14,FALSE) -> PRIMARIA | W30: ESC. CHANGUINOLA AMERICAN ACADEMY | Y30: ESC. BILINGÜE FINCA 66 | Z30: 1 | AA30: 348 | AB30: 823 | AC30: 432 | AE30: Bocas del Toro | AF30: 68
A31: 1 | B31: 53 | C31: Municipio Chiriquí Grande (Cabecera) | D31: Bocas del Toro | E31: Chiriquí Grande | F31: Chiriquí Grande | G31: FO | H31: 8.948784 | I31: -82.116083 | J31: 42950 | K31: =(TODAY()-Table1[[#This Row],[Fecha de Activación]])/365 -> 8.3643836 | L31: =VLOOKUP(Table1[[#This Row],[Nombre (Punto de Acceso)]],BD_DataTransferida!A44:G97,7,FALSE) -> 339 | M31: =VLOOKUP(Table1[[#This Row],[Nombre (Punto de Acceso)]],BD_Sesiones!A43:I97,7,FALSE) -> 4017 | N31: =TRUNC(Table1[[#This Row],[Datos (GB)]]/Table1[[#This Row],[Cantidad de Sesiones]]*1024) -> 86 | O31: =VLOOKUP(Table1[[#This Row],[Nombre (Punto de Acceso)]],BD_Sesiones!A43:I97,8,FALSE) -> C&W Panamá | P31: =VLOOKUP(Table1[[#This Row],[Nombre (Punto de Acceso)]],BD_Sesiones!A43:I97,9,FALSE) -> Sí | W31: ESC. ADVENTISTA BILINGÜE DE ALMIRANTE | Y31: ESC. BILINGÜE EL SILENCIO | Z31: 1 | AA31: 210 | AB31: 1775 | AC31: 121 | AE31: Grand Total | AF31: 98
A32: 1 | B32: 13 | C32: BDA | D32: Bocas del Toro | E32: Changuinola | F32: Changuinola | G32: FO | H32: 9.437215 | I32: -82.519311 | J32: 42926 | K32: =(TODAY()-Table1[[#This Row],[Fecha de Activación]])/365 -> 8.430137 | L32: =VLOOKUP(Table1[[#This Row],[Nombre (Punto de Acceso)]],BD_DataTransferida!A3:G56,7,FALSE) -> 134 | M32: =VLOOKUP(Table1[[#This Row],[Nombre (Punto de Acceso)]],BD_Sesiones!A2:I56,7,FALSE) -> 1654 | N32: =TRUNC(Table1[[#This Row],[Datos (GB)]]/Table1[[#This Row],[Cantidad de Sesiones]]*1024) -> 82 | O32: =VLOOKUP(Table1[[#This Row],[Nombre (Punto de Acceso)]],BD_Sesiones!A2:I56,8,FALSE) -> C&W Panamá | P32: =VLOOKUP(Table1[[#This Row],[Nombre (Punto de Acceso)]],BD_Sesiones!A2:I56,9,FALSE) -> Sí | W32: ESC. AGUA SALUD | Y32: ESC. FINCA 03 | Z32: 1 | AA32: 124 | AB32: 313 | AC32: 405
A33: 1 | B33: 30 | C33: Escuela Finca 44 | D33: Bocas del Toro | E33: Changuinola | F33: Changuinola | G33: FO | H33: 9.474577 | I33: -82.482878 | J33: 42912 | K33: =(TODAY()-Table1[[#This Row],[Fecha de Activación]])/365 -> 8.4684932 | L33: =VLOOKUP(Table1[[#This Row],[Nombre (Punto de Acceso)]],BD_DataTransferida!A26:G79,7,FALSE) -> 100 | M33: =VLOOKUP(Table1[[#This Row],[Nombre (Punto de Acceso)]],BD_Sesiones!A25:I79,7,FALSE) -> 1337 | N33: =TRUNC(Table1[[#This Row],[Datos (GB)]]/Table1[[#This Row],[Cantidad de Sesiones]]*1024) -> 76 | O33: =VLOOKUP(Table1[[#This Row],[Nombre (Punto de Acceso)]],BD_Sesiones!A25:I79,8,FALSE) -> C&W Panamá | P33: =VLOOKUP(Table1[[#This Row],[Nombre (Punto de Acceso)]],BD_Sesiones!A25:I79,9,FALSE) -> Sí | Q33: ESC. FINCA 44 | R33: =VLOOKUP(Table1[[#This Row],[Nombres de Centros Educativos (MEDUCA)]],BD_Meduca!A8:N55,9,FALSE) -> OFICIAL | S33: =VLOOKUP(Table1[[#This Row],[Nombres de Centros Educativos (MEDUCA)]],BD_Meduca!A8:N55,10,FALSE) -> ACTIVA | T33: =VLOOKUP(Table1[[#This Row],[Nombres de Centros Educativos (MEDUCA)]],BD_Meduca!A8:N58,7,FALSE) -> URBANA | U33: =VLOOKUP(Table1[[#This Row],[Nombres de Centros Educativos (MEDUCA)]],BD_Meduca!A8:N58,11,FALSE) -> NO | V33: =VLOOKUP(Table1[[#This Row],[Nombres de Centros Educativos (MEDUCA)]],BD_Meduca!A8:N58,14,FALSE) -> PREESCOLAR-PRIMARIA | W33: ESC. AGUACATE | Y33: ESC. FINCA 41 | Z33: 1 | AA33: 83 | AB33: 1418 | AC33: 59
A34: 1 | B34: 20 | C34: Instituto Profesional y técnico de Bocas del Toro | D34: Bocas del Toro | E34: Changuinola | F34: Changuinola | G34: HFC | H34: 9.47141 | I34: -82.51574 | J34: 42912 | K34: =(TODAY()-Table1[[#This Row],[Fecha de Activación]])/365 -> 8.4684932 | L34: =VLOOKUP(Table1[[#This Row],[Nombre (Punto de Acceso)]],BD_DataTransferida!A42:G95,7,FALSE) -> 318 | M34: =VLOOKUP(Table1[[#This Row],[Nombre (Punto de Acceso)]],BD_Sesiones!A41:I95,7,FALSE) -> 4450 | N34: =TRUNC(Table1[[#This Row],[Datos (GB)]]/Table1[[#This Row],[Cantidad de Sesiones]]*1024) -> 73 | O34: =VLOOKUP(Table1[[#This Row],[Nombre (Punto de Acceso)]],BD_Sesiones!A41:I95,8,FALSE) -> C&W Panamá | P34: =VLOOKUP(Table1[[#This Row],[Nombre (Punto de Acceso)]],BD_Sesiones!A41:I95,9,FALSE) -> Sí | Q34: I.P.T. BOCAS DEL TORO | R34: =VLOOKUP(Table1[[#This Row],[Nombres de Centros Educativos (MEDUCA)]],BD_Meduca!A11:N71,9,FALSE) -> OFICIAL | S34: =VLOOKUP(Table1[[#This Row],[Nombres de Centros Educativos (MEDUCA)]],BD_Meduca!A11:N71,10,FALSE) -> ACTIVA | T34: =VLOOKUP(Table1[[#This Row],[Nombres de Centros Educativos (MEDUCA)]],BD_Meduca!A12:N74,7,FALSE) -> RURAL | U34: =VLOOKUP(Table1[[#This Row],[Nombres de Centros Educativos (MEDUCA)]],BD_Meduca!A12:N74,11,FALSE) -> NO | V34: =VLOOKUP(Table1[[#This Row],[Nombres de Centros Educativos (MEDUCA)]],BD_Meduca!A12:N74,14,FALSE) -> PRIMARIA | W34: ESC. ALTO CAÑA | Y34: ESC. FINCA 41 ANEXA GUABITO | Z34: 1 | AA34: 133 | AB34: 996 | AC34: 136
A35: 1 | B35: 39 | C35: Universidad de Panamá El Empalme | D35: Bocas del Toro | E35: Changuinola | F35: El Empalme | G35: FO | H35: 9.415669 | I35: -82.526246 | J35: 42927 | K35: =(TODAY()-Table1[[#This Row],[Fecha de Activación]])/365 -> 8.4273973 | L35: =VLOOKUP(Table1[[#This Row],[Nombre (Punto de Acceso)]],BD_DataTransferida!A53:G106,7,FALSE) -> 100 | M35: =VLOOKUP(Table1[[#This Row],[Nombre (Punto de Acceso)]],BD_Sesiones!A52:I106,7,FALSE) -> 1434 | N35: =TRUNC(Table1[[#This Row],[Datos (GB)]]/Table1[[#This Row],[Cantidad de Sesiones]]*1024) -> 71 | O35: =VLOOKUP(Table1[[#This Row],[Nombre (Punto de Acceso)]],BD_Sesiones!A52:I106,8,FALSE) -> C&W Panamá | P35: =VLOOKUP(Table1[[#This Row],[Nombre (Punto de Acceso)]],BD_Sesiones!A52:I106,9,FALSE) -> Sí | W35: ESC. ALTO DE YORKIN | Y35: ESC. FINCA 43 | Z35: 1 | AA35: 182 | AB35: 2159 | AC35: 86
A36: 1 | B36: 27 | C36: C.E.B.G. Finca 32 | D36: Bocas del Toro | E36: Changuinola | F36: Changuinola | G36: HFC | H36: 9.427024 | I36: -82.555804 | J36: 42913 | K36: =(TODAY()-Table1[[#This Row],[Fecha de Activación]])/365 -> 8.4657534 | L36: =VLOOKUP(Table1[[#This Row],[Nombre (Punto de Acceso)]],BD_DataTransferida!A7:G60,7,FALSE) -> 224 | M36: =VLOOKUP(Table1[[#This Row],[Nombre (Punto de Acceso)]],BD_Sesiones!A6:I60,7,FALSE) -> 3301 | N36: =TRUNC(Table1[[#This Row],[Datos (GB)]]/Table1[[#This Row],[Cantidad de Sesiones]]*1024) -> 69 | O36: =VLOOKUP(Table1[[#This Row],[Nombre (Punto de Acceso)]],BD_Sesiones!A6:I60,8,FALSE) -> C&W Panamá | P36: =VLOOKUP(Table1[[#This Row],[Nombre (Punto de Acceso)]],BD_Sesiones!A6:I60,9,FALSE) -> Sí | Q36: ESC. BILINGÜE FINCA 32 | R36: =VLOOKUP(Table1[[#This Row],[Nombres de Centros Educativos (MEDUCA)]],BD_Meduca!A4:N36,9,FALSE) -> PARTICULAR | S36: =VLOOKUP(Table1[[#This Row],[Nombres de Centros Educativos (MEDUCA)]],BD_Meduca!A4:N36,10,FALSE) -> ACTIVA | T36: =VLOOKUP(Table1[[#This Row],[Nombres de Centros Educativos (MEDUCA)]],BD_Meduca!A7:N39,7,FALSE) -> URBANA | U36: =VLOOKUP(Table1[[#This Row],[Nombres de Centros Educativos (MEDUCA)]],BD_Meduca!A7:N39,11,FALSE) -> NO | V36: =VLOOKUP(Table1[[#This Row],[Nombres de Centros Educativos (MEDUCA)]],BD_Meduca!A7:N39,14,FALSE) -> PREESCOLAR-PRIMARIA-PREMEDIA-MEDIA ACADÉMICA | W36: ESC. ALTO DOS CAÑOS ANEXA | Y36: ESC. FINCA 44 | Z36: 1 | AA36: 100 | AB36: 1337 | AC36: 76
A37: 1 | B37: 31 | C37: Escuela Finca 64 | D37: Bocas del Toro | E37: Changuinola | F37: Changuinola | G37: FO | H37: 9.458968 | I37: -82.496082 | J37: 42949 | K37: =(TODAY()-Table1[[#This Row],[Fecha de Activación]])/365 -> 8.3671233 | L37: =VLOOKUP(Table1[[#This Row],[Nombre (Punto de Acceso)]],BD_DataTransferida!A28:G81,7,FALSE) -> 372 | M37: =VLOOKUP(Table1[[#This Row],[Nombre (Punto de Acceso)]],BD_Sesiones!A27:I81,7,FALSE) -> 5681 | N37: =TRUNC(Table1[[#This Row],[Datos (GB)]]/Table1[[#This Row],[Cantidad de Sesiones]]*1024) -> 67 | O37: =VLOOKUP(Table1[[#This Row],[Nombre (Punto de Acceso)]],BD_Sesiones!A27:I81,8,FALSE) -> C&W Panamá | P37: =VLOOKUP(Table1[[#This Row],[Nombre (Punto de Acceso)]],BD_Sesiones!A27:I81,9,FALSE) -> Sí | Q37: ESC. FINCA 64 | R37: =VLOOKUP(Table1[[#This Row],[Nombres de Centros Educativos (MEDUCA)]],BD_Meduca!A8:N57,9,FALSE) -> OFICIAL | S37: =VLOOKUP(Table1[[#This Row],[Nombres de Centros Educativos (MEDUCA)]],BD_Meduca!A8:N57,10,FALSE) -> ACTIVA | T37: =VLOOKUP(Table1[[#This Row],[Nombres de Centros Educativos (MEDUCA)]],BD_Meduca!A8:N60,7,FALSE) -> URBANA | U37: =VLOOKUP(Table1[[#This Row],[Nombres de Centros Educativos (MEDUCA)]],BD_Meduca!A8:N60,11,FALSE) -> NO | V37: =VLOOKUP(Table1[[#This Row],[Nombres de Centros Educativos (MEDUCA)]],BD_Meduca!A8:N60,14,FALSE) -> PREESCOLAR-PRIMARIA | W37: ESC. ALTO LA GLORIA | Y37: ESC. FINCA 54 | Z37: 1 | AA37: 202 | AB37: 1776 | AC37: 116 | AE37: Tipo de Conexión | AF37: Cantidades
A38: 1 | B38: 33 | C38: C.E.B.G. Finca 04 | D38: Bocas del Toro | E38: Changuinola | F38: El Empalme | G38: FO | H38: 9.405815 | I38: -82.50158 | J38: 42913 | K38: =(TODAY()-Table1[[#This Row],[Fecha de Activación]])/365 -> 8.4657534 | L38: =VLOOKUP(Table1[[#This Row],[Nombre (Punto de Acceso)]],BD_DataTransferida!A6:G59,7,FALSE) -> 137 | M38: =VLOOKUP(Table1[[#This Row],[Nombre (Punto de Acceso)]],BD_Sesiones!A5:I59,7,FALSE) -> 2157 | N38: =TRUNC(Table1[[#This Row],[Datos (GB)]]/Table1[[#This Row],[Cantidad de Sesiones]]*1024) -> 65 | O38: =VLOOKUP(Table1[[#This Row],[Nombre (Punto de Acceso)]],BD_Sesiones!A5:I59,8,FALSE) -> C&W Panamá | P38: =VLOOKUP(Table1[[#This Row],[Nombre (Punto de Acceso)]],BD_Sesiones!A5:I59,9,FALSE) -> Sí | Q38: C.E.B.G. BILINGÜE FINCA 04 | R38: =VLOOKUP(Table1[[#This Row],[Nombres de Centros Educativos (MEDUCA)]],BD_Meduca!A3:N35,9,FALSE) -> OFICIAL | S38: =VLOOKUP(Table1[[#This Row],[Nombres de Centros Educativos (MEDUCA)]],BD_Meduca!A3:N35,10,FALSE) -> ACTIVA | T38: RURAL | U38: NO | V38: PREESCOLAR-PRIMARIA-PREMEDIA | W38: ESC. ALTO PITA | Y38: ESC. FINCA 64 | Z38: 1 | AA38: 372 | AB38: 5681 | AC38: 67 | AE38: FO (Fibra Óptica) | AF38: 48
A39: 1 | B39: 6 | C39: Col. Sec. de Almirante | D39: Bocas del Toro | E39: Almirante | F39: Puerto Almirante | G39: FO | H39: 9.299741 | I39: -82.413301 | J39: 42926 | K39: =(TODAY()-Table1[[#This Row],[Fecha de Activación]])/365 -> 8.430137 | L39: =VLOOKUP(Table1[[#This Row],[Nombre (Punto de Acceso)]],BD_DataTransferida!A12:G65,7,FALSE) -> 120 | M39: =VLOOKUP(Table1[[#This Row],[Nombre (Punto de Acceso)]],BD_Sesiones!A11:I65,7,FALSE) -> 1993 | N39: =TRUNC(Table1[[#This Row],[Datos (GB)]]/Table1[[#This Row],[Cantidad de Sesiones]]*1024) -> 61 | O39: =VLOOKUP(Table1[[#This Row],[Nombre (Punto de Acceso)]],BD_Sesiones!A11:I65,8,FALSE) -> C&W Panamá | P39: =VLOOKUP(Table1[[#This Row],[Nombre (Punto de Acceso)]],BD_Sesiones!A11:I65,9,FALSE) -> Sí | Q39: COLEGIO SECUNDARIO DE ALMIRANTE | R39: =VLOOKUP(Table1[[#This Row],[Nombres de Centros Educativos (MEDUCA)]],BD_Meduca!A7:N41,9,FALSE) -> OFICIAL | S39: =VLOOKUP(Table1[[#This Row],[Nombres de Centros Educativos (MEDUCA)]],BD_Meduca!A7:N41,10,FALSE) -> ACTIVA | T39: =VLOOKUP(Table1[[#This Row],[Nombres de Centros Educativos (MEDUCA)]],BD_Meduca!A7:N44,7,FALSE) -> RURAL | U39: =VLOOKUP(Table1[[#This Row],[Nombres de Centros Educativos (MEDUCA)]],BD_Meduca!A7:N44,11,FALSE) -> NO | V39: =VLOOKUP(Table1[[#This Row],[Nombres de Centros Educativos (MEDUCA)]],BD_Meduca!A7:N44,14,FALSE) -> PRIMARIA | W39: ESC. ALTO REFUGIO | Y39: ESC. FINCA 67 | Z39: 1 | AA39: 380 | AB39: 3385 | AC39: 114 | AE39: PTP (Punto a Punto) | AF39: 3
A40: 1 | B40: 1651 | C40: Hospital Guillermo Sánchez Borbón | D40: Bocas del Toro | E40: Bocas del Toro | F40: Bocas del Toro | G40: FO | H40: 9.360542 | I40: -82.253091 | L40: =VLOOKUP(Table1[[#This Row],[Nombre (Punto de Acceso)]],BD_DataTransferida!A39:G92,7,FALSE) -> 139 | M40: =VLOOKUP(Table1[[#This Row],[Nombre (Punto de Acceso)]],BD_Sesiones!A38:I92,7,FALSE) -> 2292 | N40: =TRUNC(Table1[[#This Row],[Datos (GB)]]/Table1[[#This Row],[Cantidad de Sesiones]]*1024) -> 62 | O40: =VLOOKUP(Table1[[#This Row],[Nombre (Punto de Acceso)]],BD_Sesiones!A38:I92,8,FALSE) -> C&W Panamá | P40: =VLOOKUP(Table1[[#This Row],[Nombre (Punto de Acceso)]],BD_Sesiones!A38:I92,9,FALSE) -> Sí | W40: ESC. ALTO ROMERO | Y40: ESC. PUENTE BLANCO | Z40: 1 | AA40: 718 | AB40: 2808 | AC40: 261 | AE40: HFC (Híbrido de Fibra Coaxial) | AF40: 2
...

Sheet BD_PuntosDeAcceso
A1: Nombre | B1: Región | C1: PA | D1: Provincia | E1: Distrito | F1: Corregimiento | G1: Tipo UM | H1: Latitud | I1: Longitud | J1: Fecha de Activación
A2: Autoridad de Turismo de Panamá | B2: 1 | C2: 1629 | D2: Bocas del Toro | E2: Bocas del Toro | F2: Bocas del Toro | G2: FO | H2: 9.33908 | I2: -82.23963
A3: BDA | B3: 1 | C3: 13 | D3: Bocas del Toro | E3: Changuinola | F3: Changuinola | G3: FO | H3: 9.437215 | I3: -82.519311 | J3: 10/07/2017
A4: Bomberos Isla Colon | B4: 1 | C4: 1369 | D4: Bocas del Toro | E4: Bocas del Toro | F4: Bocas del Toro | G4: FO | H4: 9.203042 | I4: -82.142238 | J4: 23/11/2017
A5: C.E.B.G. Dionisia G. de Ayarza | B5: 1 | C5: 51 | D5: Bocas del Toro | E5: Chiriquí Grande | F5: Chiriquí Grande | G5: FO | H5: 8.945522 | I5: -82.115149 | J5: 03/08/2017
A6: C.E.B.G. Finca 04 | B6: 1 | C6: 33 | D6: Bocas del Toro | E6: Changuinola | F6: El Empalme | G6: FO | H6: 9.405815 | I6: -82.50158 | J6: 27/06/2017
A7: C.E.B.G. Finca 32 | B7: 1 | C7: 27 | D7: Bocas del Toro | E7: Changuinola | F7: Changuinola | G7: HFC | H7: 9.427024 | I7: -82.555804 | J7: 27/06/2017
A8: C.E.B.G. FINCA 62 | B8: 1 | C8: 28 | D8: Bocas del Toro | E8: Changuinola | F8: Changuinola | G8: PTP | H8: 9.437268 | I8: -82.497184 | J8: 26/06/2017
A9: C.E.B.G. Guabito | B9: 1 | C9: 42 | D9: Bocas del Toro | E9: Changuinola | F9: Guabito | G9: FO | H9: 9.492023 | I9: -82.611638 | J9: 11/07/2017
A10: C.E.B.G. PUNTA PEÑA | B10: 1 | C10: 55 | D10: Bocas del Toro | E10: Chiriquí Grande | F10: Punta Peña | G10: FO | H10: 8.913516 | I10: -82.186711 | J10: 28/06/2017
A11: CEBG Nievecita | B11: 1 | C11: 1380 | D11: Bocas del Toro | E11: Changuinola | F11: Las Tablas | G11: FO | H11: 9.543161 | I11: -82.739405 | J11: 19/12/2017
A12: Col. Sec. de Almirante | B12: 1 | C12: 6 | D12: Bocas del Toro | E12: Almirante | F12: Puerto Almirante | G12: FO | H12: 9.299741 | I12: -82.413301 | J12: 10/07/2017
A13: Colegio Rogelio Josué Ibarra | B13: 1 | C13: 1 | D13: Bocas del Toro | E13: Bocas del Toro | F13: Bocas del Toro | G13: FO | H13: 9.340654 | I13: -82.242499 | J13: 12/07/2017
A14: Colegio Secundario de Guabito | B14: 1 | C14: 43 | D14: Bocas del Toro | E14: Changuinola | F14: Guabito | G14: FO | H14: 9.488559 | I14: -82.60768 | J14: 11/07/2017
... A38: HOSPITAL DE CHIRIQUI GRANDE | B38: 1 | C38: 1440 | D38: Bocas del Toro | E38: Chiriquí Grande | F38: Rambala | G38: FO | H38: 8.930188 | I38: -82.182191 | J38: 18/09/2018
A39: Hospital Guillermo Sánchez Borbón | B39: 1 | C39: 1651 | D39: Bocas del Toro | E39: Bocas del Toro | F39: Bocas del Toro | G39: FO | H39: 9.360542 | I39: -82.253091
A40: I.P.T. Chiriquí Grande | B40: 1 | C40: 52 | D40: Bocas del Toro | E40: Chiriquí Grande | F40: Chiriquí Grande | G40: FO | H40: 8.918024 | I40: -82.184955 | J40: 03/08/2017
A41: I.P.T. EL SILENCIO | B41: 1 | C41: 38 | D41: Bocas del Toro | E41: Changuinola | F41: El Empalme | G41: FO | H41: 9.375363 | I41: -82.528324 | J41: 27/06/2017
A42: Instituto Profesional y técnico de Bocas del Toro | B42: 1 | C42: 20 | D42: Bocas del Toro | E42: Changuinola | F42: Changuinola | G42: HFC | H42: 9.47141 | I42: -82.51574 | J42: 26/06/2017
A43: MIDES Changuinola | B43: 1 | C43: 1582 | D43: Bocas del Toro | E43: Changuinola | F43: Changuinola | G43: PTP | H43: 9.45056 | I43: -82.52094 | J43: 05/06/2019
A44: Municipio Chiriquí Grande (Cabecera) | B44: 1 | C44: 53 | D44: Bocas del Toro | E44: Chiriquí Grande | F44: Chiriquí Grande | G44: FO | H44: 8.948784 | I44: -82.116083 | J44: 03/08/2017
A45: Palacio Municipal Changuinola | B45: 1 | C45: 21 | D45: Bocas del Toro | E45: Changuinola | F45: Changuinola | G45: FO | H45: 9.454582 | I45: -82.516882 | J45: 26/06/2017
A46: Parque de la escuela de changuinola | B46: 1 | C46: 22 | D46: Bocas del Toro | E46: Changuinola | F46: Changuinola | G46: FO | H46: 9.456052 | I46: -82.514567 | J46: 11/07/2017
A47: Parque de Rambala | B47: 1 | C47: 1367 | D47: Bocas del Toro | E47: Chiriquí Grande | F47: Rambala | G47: FO | H47: 8.917832 | I47: -82.185001 | J47: 03/08/2017
A48: Parque Simón Bolívar | B48: 1 | C48: 5 | D48: Bocas del Toro | E48: Bocas del Toro | F48: Bocas del Toro | G48: FO | H48: 9.340183 | I48: -82.240631 | J48: 12/07/2017
A49: Policia de la Niñez y Adolescencia | B49: 1 | C49: 24 | D49: Bocas del Toro | E49: Changuinola | F49: Changuinola | G49: FO | H49: 9.477634 | I49: -82.508425 | J49: 27/06/2017
A50: Policía Nacional Changuinola | B50: 1 | C50: 1650 | D50: Bocas del Toro | E50: Changuinola | F50: Changuinola | G50: FO | H50: 9.44855 | I50: -82.518296
A51: Policlínica de Guabito CSS | B51: 1 | C51: 49 | D51: Bocas del Toro | E51: Changuinola | F51: Guabito | G51: FO | H51: 9.49632 | I51: -82.610203 | J51: 28/06/2017
A52: Terminal de Transporte Sincotavecop | B52: 1 | C52: 26 | D52: Bocas del Toro | E52: Changuinola | F52: Changuinola | G52: FO | H52: 9.449858 | I52: -82.518679 | J52: 29/06/2017
A53: Universidad de Panamá El Empalme | B53: 1 | C53: 39 | D53: Bocas del Toro | E53: Changuinola | F53: El Empalme | G53: FO | H53: 9.415669 | I53: -82.526246 | J53: 11/07/2017
A54: Universidad de Panamá- Sede Agropecuaria | B54: 1 | C54: 40 | D54: Bocas del Toro | E54: Changuinola | F54: El Empalme | G54: FO | H54: 9.495357 | I54: -82.586637 | J54: 27/06/2017
A55: UTP El Empalme | B55: 1 | C55: 41 | D55: Bocas del Toro | E55: Changuinola | F55: El Empalme | G55: FO | H55: 9.421975 | I55: -82.523321 | J55: 27/06/2017

Sheet BD_DataTransferida
A1: Nombre | B1: Región | C1: PA | D1: Provincia | E1: Distrito | F1: Corregimiento | G1: Datos (GB)
A2: AMP - Isla Colón | B2: 1 | C2: 1668 | D2: Bocas del Toro | E2: Bocas del Toro | F2: Bocas del Toro | G2: 22
A3: BDA | B3: 1 | C3: 13 | D3: Bocas del Toro | E3: Changuinola | F3: Changuinola | G3: 134
A4: Bomberos Isla Colon | B4: 1 | C4: 1369 | D4: Bocas del Toro | E4: Bocas del Toro | F4: Bocas del Toro | G4: 26
A5: C.E.B.G. Dionisia G. de Ayarza | B5: 1 | C5: 51 | D5: Bocas del Toro | E5: Chiriquí Grande | F5: Chiriquí Grande | G5: 139
A6: C.E.B.G. Finca 04 | B6: 1 | C6: 33 | D6: Bocas del Toro | E6: Changuinola | F6: El Empalme | G6: 137
A7: C.E.B.G. Finca 32 | B7: 1 | C7: 27 | D7: Bocas del Toro | E7: Changuinola | F7: Changuinola | G7: 224
A8: C.E.B.G. FINCA 62 | B8: 1 | C8: 28 | D8: Bocas del Toro | E8: Changuinola | F8: Changuinola | G8: 279
A9: C.E.B.G. Guabito | B9: 1 | C9: 42 | D9: Bocas del Toro | E9: Changuinola | F9: Guabito | G9: 354
A10: C.E.B.G. PUNTA PEÑA | B10: 1 | C10: 55 | D10: Bocas del Toro | E10: Chiriquí Grande | F10: Punta Peña | G10: 407
A11: CEBG Nievecita | B11: 1 | C11: 1380 | D11: Bocas del Toro | E11: Changuinola | F11: Las Tablas | G11: 727
A12: Col. Sec. de Almirante | B12: 1 | C12: 6 | D12: Bocas del Toro | E12: Almirante | F12: Puerto Almirante | G12: 120
A13: Colegio Rogelio Josué Ibarra | B13: 1 | C13: 1 | D13: Bocas del Toro | E13: Bocas del Toro | F13: Bocas del Toro | G13: 39
... A55: UTP El Empalme | B55: 1 | C55: 41 | D55: Bocas del Toro | E55: Changuinola | F55: El Empalme | G55: 144

Sheet BD_Sesiones
A1: Nombre | B1: Región | C1: PA | D1: Provincia | E1: Distrito | F1: Corregimiento | G1: Total | H1: Proveedor | I1: Disponible
A2: AMP - Isla Colón | B2: 1 | C2: 1668 | D2: Bocas del Toro | E2: Bocas del Toro | F2: Bocas del Toro | G2: 800 | H2: C&W Panamá | I2: Sí
A3: BDA | B3: 1 | C3: 13 | D3: Bocas del Toro | E3: Changuinola | F3: Changuinola | G3: 1654 | H3: C&W Panamá | I3: Sí
A4: Bomberos Isla Colon | B4: 1 | C4: 1369 | D4: Bocas del Toro | E4: Bocas del Toro | F4: Bocas del Toro | G4: 1091 | H4: C&W Panamá | I4: Sí
A5: C.E.B.G. Dionisia G. de Ayarza | B5: 1 | C5: 51 | D5: Bocas del Toro | E5: Chiriquí Grande | F5: Chiriquí Grande | G5: 1098 | H5: C&W Panamá | I5: Sí
A6: C.E.B.G. Finca 04 | B6: 1 | C6: 33 | D6: Bocas del Toro | E6: Changuinola | F6: El Empalme | G6: 2157 | H6: C&W Panamá | I6: Sí
A7: C.E.B.G. Finca 32 | B7: 1 | C7: 27 | D7: Bocas del Toro | E7: Changuinola | F7: Changuinola | G7: 3301 | H7: C&W Panamá | I7: Sí
A8: C.E.B.G. FINCA 62 | B8: 1 | C8: 28 | D8: Bocas del Toro | E8: Changuinola | F8: Changuinola | G8: 4745 | H8: C&W Panamá | I8: Sí
A9: C.E.B.G. Guabito | B9: 1 | C9: 42 | D9: Bocas del Toro | E9: Changuinola | F9: Guabito | G9: 3998 | H9: C&W Panamá | I9: Sí
A10: C.E.B.G. PUNTA PEÑA | B10: 1 | C10: 55 | D10: Bocas del Toro | E10: Chiriquí Grande | F10: Punta Peña | G10: 2928 | H10: C&W Panamá | I10: Sí
A11: CEBG Nievecita | B11: 1 | C11: 1380 | D11: Bocas del Toro | E11: Changuinola | F11: Las Tablas | G11: 3780 | H11: C&W Panamá | I11: Sí
A12: Col. Sec. de Almirante | B12: 1 | C12: 6 | D12: Bocas del Toro | E12: Almirante | F12: Puerto Almirante | G12: 1993 | H12: C&W Panamá | I12: Sí
A13: Colegio Rogelio Josué Ibarra | B13: 1 | C13: 1 | D13: Bocas del Toro | E13: Bocas del Toro | F13: Bocas del Toro | G13: 453 | H13: C&W Panamá | I13: Sí
... A55: UTP El Empalme | B55: 1 | C55: 41 | D55: Bocas del Toro | E55: Changuinola | F55: El Empalme | G55: 1503 | H55: C&W Panamá | I55: Sí

Sheet BD_Meduca
A1: Nombre del Centro Educativo | B1: Marco Muestral -Sistema Educativo | C1: Provincia | D1: Distrito | E1: Corregimiento | F1: Región Escolar | G1: Área | H1: Áreas Comarcales | I1: Dependencia | J1: Estatus | K1: Indigena | L1: Decretos (Creación, funcionamiento, cambio nombre, ampliación) | M1: Otros Decretos relacionados(Cambio de nombre, ampliacion, cierre) | N1: Oferta 2023 | O1: Bachiller
